<mujoco model="urdf_turtle_v2">
  <compiler angle="radian"/>
  <option solver="Newton" tolerance="1e-6" integrator="implicitfast"/>

  <extension>
    <plugin plugin="mujoco.elasticity.shell"/>
  </extension>

  <worldbody>

    <body name="frontrightflipper" pos="-0.011447 -0.026757 0.064797" quat="0.00296594 0.707095 0.00410249 0.707101">
        <inertial pos="0.0627381 0.0025922 0.0125462" quat="0.501508 0.494858 0.498397 0.505179"
                  mass="0.0291756" diaginertia="2.30001e-05 1.95463e-05 3.82772e-06"/>
        <joint name="frontrightflipperjoint" type="hinge" pos="0 0 0" axis="0 0 1"
               range="-0.64 1.571" actuatorfrcrange="-0.42 0.42" frictionloss="0.1"/>
       
        <!-- Base mesh (Rigid) -->
        <geom type="mesh" mesh="frontrightflipperlink" rgba="1 0 0 1" friction="1.0 0.5 0.5"
              solref="0.02 1" solimp="0.9 0.95 0.001"/>

        <flexcomp name="blurb" type="mesh" file="frontrightflipperlink.obj" pos="0 0 0" dim="2"  
                  radius="0.002" rgba="0 0.8 0.8 1" mass="0.05">
            <edge equality="true" damping="10"/>
            <contact solref="0.01 1" solimp="0.9 0.95 0.001" selfcollide="auto"/>
           
            <plugin plugin="mujoco.elasticity.shell">
                <config key="poisson" value="0.3"/>
                <config key="thickness" value="5e-3"/>
                <config key="young" value="1e5"/>
            </plugin>

            <pin id="0 1 2 3 4 5 6 7 8 9 10 11 12 13 14 15 16 17 18 19 20 21 22 23 24 25"/>
        </flexcomp>

    </body>

  </worldbody>
</mujoco>
