<mujoco model="urdf_turtle_v2">
  <compiler angle="radian"/>

  <asset>
    <mesh name="base_link" file="base_link.STL"/>
    <mesh name="backrightlink" file="backrightlink.STL"/>
    <mesh name="backleftlink" file="backleftlink.STL"/>
    <mesh name="frontrighthiplink" file="frontrighthiplink.STL"/>
    <mesh name="frontrightflipperlink" file="frontrightflipperlink.STL"/>
    <mesh name="frontlefthiplink" file="frontlefthiplink.STL"/>
    <mesh name="frontleftflipperlink" file="frontleftflipperlink.STL"/>
  </asset>

  <worldbody>
    <geom type="mesh" rgba="0.752941 0.752941 0.752941 1" mesh="base_link"/>
    <body name="backrightlink" pos="-0.044464 -0.015725 -0.023608" quat="0.820538 0.273512 -0.158716 -0.476149">
      <inertial pos="-0.000230498 -0.0259489 0.0454514" quat="0.628624 0.777697 -0.00340079 -0.00280565" mass="0.00735328" diaginertia="2.06921e-06 1.28265e-06 8.58253e-07"/>
      <joint name="backrightjoint" pos="0 0 0" axis="0 0 1" range="-0.524 1.571" actuatorfrcrange="-0.42 0.42"/>
      <geom type="mesh" rgba="1 0 0 1" mesh="backrightlink"/>
    </body>
    <body name="backleftlink" pos="-0.058724 0.022973 -0.0023055" quat="0.476146 0.158715 -0.273513 -0.82054">
      <inertial pos="3.53889e-05 -0.0259499 0.0196231" quat="0.62863 0.777704 0.000583499 0.000414911" mass="0.00735328" diaginertia="2.06921e-06 1.28265e-06 8.58253e-07"/>
      <joint name="backleftjoint" pos="0 0 0" axis="0 0 1" range="-1.571 0.524" actuatorfrcrange="-0.42 0.42"/>
      <geom type="mesh" rgba="1 0 0 1" mesh="backleftlink"/>
    </body>
    <body name="frontrighthiplink" pos="0.088599 0.007262 0.02" quat="0.613891 0.35091 -0.613893 0.350907">
      <inertial pos="0.000477612 -0.0269624 0.0548139" quat="0.990877 -0.125716 -0.000887173 -0.0485622" mass="0.0214873" diaginertia="3.29218e-06 2.49101e-06 2.10494e-06"/>
      <joint name="frontrighthipjoint" pos="0 0 0" axis="0 -5.7115e-05 1" range="-1.22 1.571" actuatorfrcrange="-0.42 0.42"/>
      <geom type="mesh" rgba="0.752941 0.752941 0.752941 1" mesh="frontrighthiplink"/>
      <body name="frontrightflipperlink" pos="-0.011447 -0.026757 0.064797" quat="0.00296594 0.707095 0.00410249 0.707101">
        <inertial pos="0.0627381 0.0025922 0.0125462" quat="0.501508 0.494858 0.498397 0.505179" mass="0.0291756" diaginertia="2.30001e-05 1.95463e-05 3.82772e-06"/>
        <joint name="frontrightflipperjoint" pos="0 0 0" axis="-0.00397829 0.394849 0.918737" range="-0.34 1.571" actuatorfrcrange="-0.42 0.42"/>
        <geom type="mesh" rgba="1 0 0 1" mesh="frontrightflipperlink"/>
      </body>
    </body>
    <body name="frontlefthiplink" pos="0.072097 0.02037 0.018766" quat="0.68222 -0.682222 -0.185942 0.185941">
      <inertial pos="0.0271358 -0.00074823 0.0228334" quat="0.73992 -0.0891628 -0.0922786 0.660343" mass="0.0214873" diaginertia="3.29236e-06 2.49208e-06 2.10369e-06"/>
      <joint name="frontlefthipjoint" pos="0 0 0" axis="0 0 -1" range="-1.571 1.22" actuatorfrcrange="-0.42 0.42"/>
      <geom type="mesh" rgba="0.752941 0.752941 0.752941 1" mesh="frontlefthiplink"/>
      <body name="frontleftflipperlink" pos="0.029345 -0.0003733 0.032817" quat="0.496813 0.503165 -0.496815 0.503167">
        <inertial pos="0.0590079 -0.000759462 0.000119837" quat="0.506667 0.499947 0.493291 0.500005" mass="0.0291756" diaginertia="2.30001e-05 1.95463e-05 3.82772e-06"/>
        <joint name="frontleftflipperjoint" pos="0 0 0" axis="0 0 1" range="-1.571 0.34" actuatorfrcrange="-0.42 0.42"/>
        <geom type="mesh" rgba="1 0.921569 0.780392 1" mesh="frontleftflipperlink"/>
      </body>
    </body>
  </worldbody>
</mujoco>
